Workbook

Sheet SOV
A1: KENNY SENG CONSTRUCTION, INC.
A2: SCHEDULE OF VALUES
A4: Payment Request #5 | C4: Date: | D4: 46013 | E4: Job: Treasure Mountain Sports Complex
A6: ITEM | B6: DESCRIPTION OF WORK | C6: SCHEDULED | D6: WORK COMPLETED | F6: MATERIALS | G6: TOT COMPLETED | H6: % COMPLETE | I6: BALANCE TO
C7: VALUE | D7: PREVIOUS | E7: THIS PERIOD | F7: ON SITE | I7: FINISH
B8: ONSITE
A9: 1 | B9: =_xlfn.XLOOKUP(A9,Detail!A3:A654,Detail!C3:C654) -> Temporary Erosion & Sediment Control | C9: 40400 | D9: 12120 | E9: =+Detail!$K3 -> 2020 | F9: 0 | G9: =D9+E9+F9 -> 14140 | H9: =G9/C9 -> 0.35 | I9: =+C9-G9 -> 26260
A10: 2 | B10: =_xlfn.XLOOKUP(A10,Detail!A4:A655,Detail!C4:C655) -> Site Demolition | C10: 582300 | D10: 8086.3132 | E10: =+Detail!K6 -> 57531.748 | F10: 0 | G10: =D10+E10+F10 -> 65618.061 | H10: =G10/C10 -> 0.11268772 | I10: =+C10-G10 -> 516681.94
A11: 3 | B11: =_xlfn.XLOOKUP(A11,Detail!A6:A656,Detail!C6:C656) -> Site Earthwork | C11: 1267100 | D11: 509852.54 | E11: =+Detail!K85 -> 0 | F11: 0 | G11: =D11+E11+F11 -> 509852.54 | H11: =G11/C11 -> 0.40237751 | I11: =+C11-G11 -> 757247.46
A12: 4 | B12: =_xlfn.XLOOKUP(A12,Detail!A7:A657,Detail!C7:C657) -> Utilities (CW,FL,SD,SS,IRR) | C12: 1215500 | D12: 425292.36 | E12: =+Detail!K107 -> 0 | F12: 0 | G12: =D12+E12+F12 -> 425292.36 | H12: =G12/C12 -> 0.34989088 | I12: =+C12-G12 -> 790207.64
A13: 5 | B13: =_xlfn.XLOOKUP(A13,Detail!A9:A658,Detail!C9:C658) -> Building Earthwork | C13: 748900 | D13: 387693.95 | E13: =+Detail!K345 -> 99267.64 | F13: 0 | G13: =D13+E13+F13 -> 486961.59 | H13: =G13/C13 -> 0.6502358 | I13: =+C13-G13 -> 261938.41
A14: 6 | B14: =_xlfn.XLOOKUP(A14,Detail!A10:A659,Detail!C10:C659) -> Structural Concrete | C14: 317600 | D14: 103643.91 | E14: =+Detail!K376 -> 61201.961 | F14: 0 | G14: =D14+E14+F14 -> 164845.87 | H14: =G14/C14 -> 0.51903613 | I14: =+C14-G14 -> 152754.13
A15: 7 | B15: =_xlfn.XLOOKUP(A15,Detail!A11:A660,Detail!C11:C660) -> Site Concrete Prep | C15: 261500 | D15: 10633.273 | E15: =+Detail!K425 -> 0 | F15: 0 | G15: =D15+E15+F15 -> 10633.273 | H15: =G15/C15 -> 0.04066261 | I15: =+C15-G15 -> 250866.73
A16: 8 | B16: =_xlfn.XLOOKUP(A16,Detail!A12:A661,Detail!C12:C661) -> Site Concrete | C16: 1367500 | D16: 172106.44 | E16: =+Detail!K464 -> 0 | F16: 0 | G16: =D16+E16+F16 -> 172106.44 | H16: =G16/C16 -> 0.1258548 | I16: =+C16-G16 -> 1195393.6
A17: 9 | B17: =_xlfn.XLOOKUP(A17,Detail!A13:A662,Detail!C13:C662) -> Hot-Mix Asphalt (Prep) | C17: 130300 | D17: 0 | E17: =_xlfn.XLOOKUP(A17,Detail!$A$3:$A$654,Detail!$AE$3:$AE$654) -> 0 | F17: 0 | G17: =D17+E17+F17 -> 0 | H17: =G17/C17 -> 0 | I17: =+C17-G17 -> 130300
A18: 10 | B18: =_xlfn.XLOOKUP(A18,Detail!A14:A663,Detail!C14:C663) -> Hot-Mix Asphalt Paving | C18: 230200 | D18: 0 | E18: =_xlfn.XLOOKUP(A18,Detail!$A$3:$A$654,Detail!$AE$3:$AE$654) -> 0 | F18: 0 | G18: =D18+E18+F18 -> 0 | H18: =G18/C18 -> 0 | I18: =+C18-G18 -> 230200
A19: 11 | B19: =_xlfn.XLOOKUP(A19,Detail!A15:A664,Detail!C15:C664) -> Pavement Markings - Striping | C19: 2910 | D19: 0 | E19: =_xlfn.XLOOKUP(A19,Detail!$A$3:$A$654,Detail!$AE$3:$AE$654) -> 0 | F19: 0 | G19: =D19+E19+F19 -> 0 | H19: =G19/C19 -> 0 | I19: =+C19-G19 -> 2910
A20: 12 | B20: =_xlfn.XLOOKUP(A20,Detail!A16:A665,Detail!C16:C665) -> Exterior Sports Equipment | C20: 818500 | D20: 236740.89 | E20: =+Detail!K508 -> 0 | G20: =D20+E20+F20 -> 236740.89 | H20: =G20/C20 -> 0.2892375 | I20: =+C20-G20 -> 581759.11
A21: 13 | B21: =_xlfn.XLOOKUP(A21,Detail!A17:A666,Detail!C17:C666) -> Turf Field Prep | C21: 2424100 | D21: 1091650.8 | E21: =+Detail!K600 -> 0 | F21: 0 | G21: =D21+E21+F21 -> 1091650.8 | H21: =G21/C21 -> 0.4503324 | I21: =+C21-G21 -> 1332449.2
A22: 14 | B22: =_xlfn.XLOOKUP(A22,Detail!A18:A667,Detail!C18:C667) -> Segmented Retaining Wall | C22: 63300 | D22: 63300 | E22: =+Detail!P627 -> 0 | F22: 0 | G22: =D22+E22+F22 -> 63300 | H22: =G22/C22 -> 1 | I22: =+C22-G22 -> 0
A23: 15 | B23: =_xlfn.XLOOKUP(A23,Detail!A19:A668,Detail!C19:C668) -> Concrete Sign Wall - Tilt Panel | C23: 24700 | D23: 0 | E23: =_xlfn.XLOOKUP(A23,Detail!$A$3:$A$654,Detail!$AE$3:$AE$654) -> 0 | F23: 0 | G23: =D23+E23+F23 -> 0 | H23: =G23/C23 -> 0 | I23: =+C23-G23 -> 24700
A24: 16 | B24: =_xlfn.XLOOKUP(A24,Detail!A20:A669,Detail!C20:C669) -> Baseball & Softball Scoreboards | C24: 63000 | D24: 0 | E24: =_xlfn.XLOOKUP(A24,Detail!$A$3:$A$654,Detail!$AE$3:$AE$654) -> 0 | F24: 0 | G24: =D24+E24+F24 -> 0 | H24: =G24/C24 -> 0 | I24: =+C24-G24 -> 63000
A25: 17 | B25: =_xlfn.XLOOKUP(A25,Detail!A21:A670,Detail!C21:C670) -> Soccer Scoreboards | C25: 65000 | D25: 0 | E25: =_xlfn.XLOOKUP(A25,Detail!$A$3:$A$654,Detail!$AE$3:$AE$654) -> 0 | F25: 0 | G25: =D25+E25+F25 -> 0 | H25: =G25/C25 -> 0 | I25: =+C25-G25 -> 65000
A26: 18 | B26: =_xlfn.XLOOKUP(A26,Detail!A22:A671,Detail!C22:C671) -> Building Demo (Concrete Slabs And Footings) | C26: 398000 | D26: 0 | E26: =+Detail!K648 -> 9045.4545 | F26: 0 | G26: =D26+E26+F26 -> 9045.4545 | H26: =G26/C26 -> 0.022727273 | I26: =+C26-G26 -> 388954.55
A27: 19 | B27: =_xlfn.XLOOKUP(A27,Detail!A23:A672,Detail!C23:C672) -> Hazwoper Training | C27: 100000 | D27: 35000 | E27: 15000 | F27: 0 | G27: =D27+E27+F27 -> 50000 | H27: =G27/C27 -> 0.5 | I27: =+C27-G27 -> 50000
B28: SUBTOTAL | C28: =SUM(C9:C27) -> 10120810 | D28: =SUM(D9:D27) -> 3056120.4 | E28: =SUM(E9:E27) -> 244066.8 | F28: =SUM(F9:F27) -> 0 | G28: =SUM(G9:G27) -> 3300187.3 | H28: =G28/C28 -> 0.32607936 | I28: =SUM(I9:I27) -> 6820622.7
B29: Change Orders
C30: 0 | D30: 0 | E30: 0 | F30: 0 | G30: =D30+E30+F30 -> 0 | H30: =IF(B30="","",(G30/C30)) | I30: =+C30-G30 -> 0
C31: 0 | D31: 0 | E31: 0 | F31: 0 | G31: =D31+E31+F31 -> 0 | H31: =IF(B31="","",(G31/C31)) | I31: =+C31-G31 -> 0
B32: SUBTOTAL | C32: =SUM(C30:C31) -> 0 | D32: =SUM(D30:D31) -> 0 | E32: =SUM(E30:E31) -> 0 | F32: =SUM(F30:F31) -> 0 | G32: =SUM(G30:G31) -> 0 | H32: =IF(B30="","",(G32/C32)) | I32: =SUM(I30:I31) -> 0
B33: TOTALS | C33: =+C32+C28 -> 10120810 | D33: =+D32+D28 -> 3056120.4 | E33: =+E32+E28 -> 244066.8 | F33: =+F32+F28 -> 0 | G33: =+G32+G28 -> 3300187.3 | H33: =G33/C33 -> 0.32607936 | I33: =+C33-G33 -> 6820622.7
C36: 10120810 | D36: 2411787.8 | E36: 532332.62 | F36: 0 | G36: 2944120.4 | H36: 0.29089771 | I36: 7176689.6

Sheet Detail
A1: ITEM | B1: PHASE | C1: DESCRIPTION OF WORK | D1: SCHEDULED VALUE | E1: COST | F1: PRICE | G1: QTY | H1: UOM | I1: UNIT PRICE | J1: 46016 | O1: 45986 | T1: 45955 | Y1: 45925 | AD1: 45894
J2: QTY | K2: AMT | L2: REM | M2: Rem Qty | N2: % Com | O2: QTY | P2: AMT | Q2: REM | R2: Rem Qty | S2: % Com | T2: QTY | U2: AMT | V2: REM | W2: Rem Qty | X2: % Com | Y2: QTY | Z2: AMT | AA2: REM | AB2: Rem Qty | AC2: % Com | AD2: QTY | AE2: AMT | AF2: REM | AG2: Rem Qty | AH2: % Com
A3: 1 | C3: Temporary Erosion & Sediment Control | D3: =_xlfn.XLOOKUP(A3,SOV!$A$9:$A$27,SOV!$C$9:$C$27) -> 40400 | E3: 29138.08 | F3: =SUM(F4) -> 40400 | K3: =SUM(K4) -> 2020 | L3: =+Q3-K4 -> 26260 | P3: =SUM(P4) -> 2020 | Q3: =+V3-P4 -> 28280 | U3: =SUM(U4) -> 2020 | V3: =+AA3-U4 -> 30300 | Z3: =SUM(Z4) -> 2020 | AA3: =SUM(AA4) -> 32320 | AE3: =SUM(AE4) -> 6060 | AF3: =SUM(AF4) -> 34340
C4: SWPPP | E4: 29138.08 | F4: =$D$3/$E$3*E4 -> 40400 | G4: 1 | H4: LS | I4: =F4/G4 -> 40400 | J4: 0.05 | K4: =+J4*$I4 -> 2020 | L4: =+Q4-K4 -> 26260 | M4: =+R4-J4 -> 0.65 | N4: =100%-(L4/$F4) -> 0.35 | O4: 0.05 | P4: =+O4*$I4 -> 2020 | Q4: =+V4-P4 -> 28280 | R4: =+W4-O4 -> 0.7 | S4: =100%-(Q4/$F4) -> 0.3 | T4: 0.05 | U4: =+T4*$I4 -> 2020 | V4: =+AA4-U4 -> 30300 | W4: =+AB4-T4 -> 0.75 | X4: =100%-(V4/$F4) -> 0.25 | Y4: 0.05 | Z4: =Y4*I4 -> 2020 | AA4: =+AF4-Z4 -> 32320 | AB4: =+AG4-Y4 -> 0.8 | AC4: =100%-(AA4/$F4) -> 0.2 | AD4: 0.15 | AE4: =AD4*I4 -> 6060 | AF4: =F4-AE4 -> 34340 | AG4: =G4-AD4 -> 0.85 | AH4: =100%-(AF4/$F4) -> 0.15
B5: 2100 | C5: SWPPP | E5: 29138.08 | F5: =$D$3/$E$3*E5 -> 40400 | G5: 1 | H5: LS | I5: =F5/G5 -> 40400 | J5: =J4 -> 0.05 | L5: =+Q5-K5 -> 0 | O5: =O4 -> 0.05 | Q5: =+V5-P5 -> 0 | T5: =T4 -> 0.05 | V5: =+AA5-U5 -> 0 | Y5: =Y4 -> 0.05 | AA5: =+AF5-Z5 -> 0 | AD5: =AD4 -> 0.15
A6: 2 | C6: Site Demolition | D6: =_xlfn.XLOOKUP(A6,SOV!$A$9:$A$27,SOV!$C$9:$C$27) -> 582300 | E6: 422513.36 | F6: =SUM(F7,F9,F13,F17,F21,F25,F33,F41,F45,F49,F53,F61,F65,F69,F77,F81) -> 582299.99 | K6: =SUM(K7:K84) -> 57531.748 | L6: =SUM(L7:L81) -> 516681.93 | P6: =SUM(P7:P84) -> 0 | Q6: =SUM(Q7:Q81) -> 574213.67 | U6: =SUM(U7:U84) -> 0 | V6: =SUM(V7:V81) -> 574213.67 | Z6: =SUM(Z7:Z84) -> 1164.5632 | AA6: =+AF6-Z6 -> 574213.67 | AE6: =SUM(AE7:AE84) -> 6921.7501 | AF6: =SUM(AF7:AF84) -> 575378.24
C7: Tree Removal | E7: 16900 | F7: =$D$6/$E$6*E7 -> 23291.263 | G7: 1 | H7: LS | I7: =F7/G7 -> 23291.263 | J7: 0.75 | K7: =+J7*$I7 -> 17468.448 | L7: =+Q7-K7 -> 1164.5632 | M7: =+R7-J7 -> 0.05 | N7: =100%-(L7/$F7) -> 0.95 | P7: =O7*I7 -> 0 | Q7: =+V7-P7 -> 18633.011 | R7: =+W7-O7 -> 0.8 | S7: =100%-(Q7/$F7) -> 0.2 | U7: =T7*D7 -> 0 | V7: =+AA7-U7 -> 18633.011 | W7: =+AB7-T7 -> 0.8 | X7: =100%-(V7/$F7) -> 0.2 | Y7: 0.05 | Z7: =Y7*I7 -> 1164.5632 | AA7: =+AF7-Z7 -> 18633.011 | AB7: =+AG7-Y7 -> 0.8 | AC7: =100%-(AA7/$F7) -> 0.2 | AD7: 0.15 | AE7: =AD7*I7 -> 3493.6895 | AF7: =F7-AE7 -> 19797.574 | AG7: =G7-AD7 -> 0.85 | AH7: =100%-(AF7/$F7) -> 0.15
B8: 2402 | C8: Tree Removal | E8: 16900 | F8: =$D$6/$E$6*E8 -> 23291.263 | G8: 1 | H8: LS | I8: =F8/G8 -> 23291.263 | K8: =+J8*$I8 -> 0 | L8: =+Q8-K8 -> 0 | M8: =+R8-J8 -> 0 | P8: =O8*I8 -> 0 | Q8: =+V8-P8 -> 0 | R8: =+W8-O8 -> 0 | U8: =T8*D8 -> 0 | V8: =+AA8-U8 -> 0 | W8: =+AB8-T8 -> 0 | Z8: =Y8*I8 -> 0 | AA8: =+AF8-Z8 -> 0 | AB8: =+AG8-Y8 -> 0 | AD8: =AD7 -> 0.15
C9: Remove Concrete Flatwork 04" | E9: 16075.12 | F9: =$D$6/$E$6*E9 -> 22154.429 | G9: 17303 | H9: SF | I9: =F9/G9 -> 1.2803808 | J9: 8003 | K9: =+J9*$I9 -> 10246.888 | L9: =+Q9-K9 -> 11907.542 | M9: =+R9-J9 -> 9300 | N9: =100%-(L9/$F9) -> 0.46252095 | O9: 0 | P9: =O9*I9 -> 0 | Q9: =+V9-P9 -> 22154.429 | R9: =+W9-O9 -> 17303 | S9: =100%-(Q9/$F9) -> 0 | T9: 0 | U9: =T9*D9 -> 0 | V9: =+AA9-U9 -> 22154.429 | W9: =+AB9-T9 -> 17303 | X9: =100%-(V9/$F9) -> 0 | Y9: 0 | Z9: =Y9*I9 -> 0 | AA9: =+AF9-Z9 -> 22154.429 | AB9: =+AG9-Y9 -> 17303 | AC9: =100%-(AA9/$F9) -> 0 | AD9: 0 | AE9: =AD9*I9 -> 0 | AF9: =F9-AE9 -> 22154.429 | AG9: =G9-AD9 -> 17303 | AH9: =100%-(AF9/$F9) -> 0
B10: 2420 | C10: Remove Concrete Flatwork | E10: 6663.73 | F10: =$D$6/$E$6*E10 -> 9183.8279 | G10: 17303 | H10: SF | I10: =F10/G10 -> 0.53076506 | K10: =+J10*$I10 -> 0 | L10: =+Q10-K10 -> 0 | M10: =+R10-J10 -> 0 | P10: =O10*I10 -> 0 | Q10: =+V10-P10 -> 0 | R10: =+W10-O10 -> 0 | U10: =T10*D10 -> 0 | V10: =+AA10-U10 -> 0 | W10: =+AB10-T10 -> 0 | Y10: =$AD$9*B10/$G$9 -> 0 | Z10: =Y10*I10 -> 0 | AA10: =+AF10-Z10 -> 0 | AB10: =+AG10-Y10 -> 0 | AD10: =$AD$9*G10/$G$9 -> 0
B11: 2490 | C11: Dump Fees | E11: 2850.67 | F11: =$D$6/$E$6*E11 -> 3928.74 | G11: 432.58 | H11: TON | I11: =F11/G11 -> 9.082112 | K11: =+J11*$I11 -> 0 | L11: =+Q11-K11 -> 0 | M11: =+R11-J11 -> 0 | P11: =O11*I11 -> 0 | Q11: =+V11-P11 -> 0 | R11: =+W11-O11 -> 0 | U11: =T11*D11 -> 0 | V11: =+AA11-U11 -> 0 | W11: =+AB11-T11 -> 0 | Y11: =$AD$9*B11/$G$9 -> 0 | Z11: =Y11*I11 -> 0 | AA11: =+AF11-Z11 -> 0 | AB11: =+AG11-Y11 -> 0 | AD11: =$AD$9*G11/$G$9 -> 0
B12: 2150 | C12: Export Trucking | E12: 6560.72 | F12: =$D$6/$E$6*E12 -> 9041.8614 | G12: 432.58 | H12: TON | I12: =F12/G12 -> 20.902172 | K12: =+J12*$I12 -> 0 | L12: =+Q12-K12 -> 0 | M12: =+R12-J12 -> 0 | P12: =O12*I12 -> 0 | Q12: =+V12-P12 -> 0 | R12: =+W12-O12 -> 0 | U12: =T12*D12 -> 0 | V12: =+AA12-U12 -> 0 | W12: =+AB12-T12 -> 0 | Y12: =$AD$9*B12/$G$9 -> 0 | Z12: =Y12*I12 -> 0 | AA12: =+AF12-Z12 -> 0 | AB12: =+AG12-Y12 -> 0 | AD12: =$AD$9*G12/$G$9 -> 0
C13: Remove Asphalt SF (03") | E13: 98784.18 | F13: =$D$6/$E$6*E13 -> 136142.51 | G13: 147064 | H13: SF | I13: =F13/G13 -> 0.92573646 | J13: 25731 | K13: =+J13*$I13 -> 23820.125 | L13: =+Q13-K13 -> 112322.38 | M13: =+R13-J13 -> 121333 | N13: =100%-(L13/$F13) -> 0.17496464 | P13: =O13*I13 -> 0 | Q13: =+V13-P13 -> 136142.51 | R13: =+W13-O13 -> 147064 | S13: =100%-(Q13/$F13) -> 0 | U13: =T13*D13 -> 0 | V13: =+AA13-U13 -> 136142.51 | W13: =+AB13-T13 -> 147064 | X13: =100%-(V13/$F13) -> 0 | Z13: =Y13*I13 -> 0 | AA13: =+AF13-Z13 -> 136142.51 | AB13: =+AG13-Y13 -> 147064 | AC13: =100%-(AA13/$F13) -> 0 | AE13: =AD13*I13 -> 0 | AF13: =F13-AE13 -> 136142.51 | AG13: =G13-AD13 -> 147064 | AH13: =100%-(AF13/$F13) -> 0
B14: 2410 | C14: Remove Asphalt | E14: 39646.07 | F14: =$D$6/$E$6*E14 -> 54639.471 | G14: 147064 | H14: SF | I14: =F14/G14 -> 0.37153533 | K14: =+J14*$I14 -> 0 | L14: =+Q14-K14 -> 0 | M14: =+R14-J14 -> 0 | P14: =O14*I14 -> 0 | Q14: =+V14-P14 -> 0 | R14: =+W14-O14 -> 0 | U14: =T14*D14 -> 0 | V14: =+AA14-U14 -> 0 | W14: =+AB14-T14 -> 0 | Y14: =$AD$13*B14/$G$13 -> 0 | Z14: =Y14*I14 -> 0 | AA14: =+AF14-Z14 -> 0 | AB14: =+AG14-Y14 -> 0 | AD14: =$AD$13*G14/$G$13 -> 0
B15: 2490 | C15: Dump Fees | E15: 17316.79 | F15: =$D$6/$E$6*E15 -> 23865.676 | G15: 2757.45 | H15: TON | I15: =F15/G15 -> 8.6549804 | K15: =+J15*$I15 -> 0 | L15: =+Q15-K15 -> 0 | M15: =+R15-J15 -> 0 | P15: =O15*I15 -> 0 | Q15: =+V15-P15 -> 0 | R15: =+W15-O15 -> 0 | U15: =T15*D15 -> 0 | V15: =+AA15-U15 -> 0 | W15: =+AB15-T15 -> 0 | Y15: =$AD$13*B15/$G$13 -> 0 | Z15: =Y15*I15 -> 0 | AA15: =+AF15-Z15 -> 0 | AB15: =+AG15-Y15 -> 0 | AD15: =$AD$13*G15/$G$13 -> 0
B16: 2150 | C16: Export Trucking | E16: 41821.33 | F16: =$D$6/$E$6*E16 -> 57637.374 | G16: 2757.45 | H16: TON | I16: =F16/G16 -> 20.902418 | K16: =+J16*$I16 -> 0 | L16: =+Q16-K16 -> 0 | M16: =+R16-J16 -> 0 | P16: =O16*I16 -> 0 | Q16: =+V16-P16 -> 0 | R16: =+W16-O16 -> 0 | U16: =T16*D16 -> 0 | V16: =+AA16-U16 -> 0 | W16: =+AB16-T16 -> 0 | Y16: =$AD$13*B16/$G$13 -> 0 | Z16: =Y16*I16 -> 0 | AA16: =+AF16-Z16 -> 0 | AB16: =+AG16-Y16 -> 0 | AD16: =$AD$13*G16/$G$13 -> 0
C17: Remove Curb/Gutter 24" | E17: 11787.9 | F17: =$D$6/$E$6*E17 -> 16245.863 | G17: 1634 | H17: LF | I17: =F17/G17 -> 9.9423886 | K17: =+J17*$I17 -> 0 | L17: =+Q17-K17 -> 16245.863 | M17: =+R17-J17 -> 1634 | N17: =100%-(L17/$F17) -> 0 | P17: =O17*I17 -> 0 | Q17: =+V17-P17 -> 16245.863 | R17: =+W17-O17 -> 1634 | S17: =100%-(Q17/$F17) -> 0 | U17: =T17*D17 -> 0 | V17: =+AA17-U17 -> 16245.863 | W17: =+AB17-T17 -> 1634 | X17: =100%-(V17/$F17) -> 0 | Z17: =Y17*I17 -> 0 | AA17: =+AF17-Z17 -> 16245.863 | AB17: =+AG17-Y17 -> 1634 | AC17: =100%-(AA17/$F17) -> 0 | AE17: =AD17*I17 -> 0 | AF17: =F17-AE17 -> 16245.863 | AG17: =G17-AD17 -> 1634 | AH17: =100%-(AF17/$F17) -> 0
B18: 2421 | C18: Remove Curb And Gutter | E18: 7521.86 | F18: =$D$6/$E$6*E18 -> 10366.487 | G18: 1634 | H18: LF | I18: =F18/G18 -> 6.344239 | K18: =+J18*$I18 -> 0 | L18: =+Q18-K18 -> 0 | M18: =+R18-J18 -> 0 | P18: =O18*I18 -> 0 | Q18: =+V18-P18 -> 0 | R18: =+W18-O18 -> 0 | U18: =T18*D18 -> 0 | V18: =+AA18-U18 -> 0 | W18: =+AB18-T18 -> 0 | Y18: =$AD$17*B18/$G$17 -> 0 | Z18: =Y18*I18 -> 0 | AA18: =+AF18-Z18 -> 0 | AB18: =+AG18-Y18 -> 0 | AD18: =$AD$17*G18/$G$17 -> 0
B19: 2490 | C19: Dump Fees | E19: 1292.17 | F19: =$D$6/$E$6*E19 -> 1780.8445 | G19: 196.08 | H19: TON | I19: =F19/G19 -> 9.0822343 | K19: =+J19*$I19 -> 0 | L19: =+Q19-K19 -> 0 | M19: =+R19-J19 -> 0 | P19: =O19*I19 -> 0 | Q19: =+V19-P19 -> 0 | R19: =+W19-O19 -> 0 | U19: =T19*D19 -> 0 | V19: =+AA19-U19 -> 0 | W19: =+AB19-T19 -> 0 | Y19: =$AD$17*B19/$G$17 -> 0 | Z19: =Y19*I19 -> 0 | AA19: =+AF19-Z19 -> 0 | AB19: =+AG19-Y19 -> 0 | AD19: =$AD$17*G19/$G$17 -> 0
B20: 2150 | C20: Export Trucking | E20: 2973.88 | F20: =$D$6/$E$6*E20 -> 4098.5457 | G20: 196.08 | H20: TON | I20: =F20/G20 -> 20.902416 | K20: =+J20*$I20 -> 0 | L20: =+Q20-K20 -> 0 | M20: =+R20-J20 -> 0 | P20: =O20*I20 -> 0 | Q20: =+V20-P20 -> 0 | R20: =+W20-O20 -> 0 | U20: =T20*D20 -> 0 | V20: =+AA20-U20 -> 0 | W20: =+AB20-T20 -> 0 | Y20: =$AD$17*B20/$G$17 -> 0 | Z20: =Y20*I20 -> 0 | AA20: =+AF20-Z20 -> 0 | AB20: =+AG20-Y20 -> 0 | AD20: =$AD$17*G20/$G$17 -> 0
C21: Remove Chain Link Fence | E21: 2487.38 | F21: =$D$6/$E$6*E21 -> 3428.0605 | G21: 811 | H21: LF | I21: =F21/G21 -> 4.226955 | K21: =+J21*$I21 -> 0 | L21: =+Q21-K21 -> 0 | M21: =+R21-J21 -> 0 | N21: =100%-(L21/$F21) -> 1 | P21: =O21*I21 -> 0 | Q21: =+V21-P21 -> 0 | R21: =+W21-O21 -> 0 | S21: =100%-(Q21/$F21) -> 1 | U21: =T21*D21 -> 0 | V21: =+AA21-U21 -> 0 | W21: =+AB21-T21 -> 0 | X21: =100%-(V21/$F21) -> 1 | Z21: =Y21*I21 -> 0 | AA21: =+AF21-Z21 -> 0 | AB21: =+AG21-Y21 -> 0 | AC21: =100%-(AA21/$F21) -> 1 | AD21: 811 | AE21: =AD21*I21 -> 3428.0605 | AF21: =F21-AE21 -> 0 | AG21: =G21-AD21 -> 0 | AH21: =100%-(AF21/$F21) -> 1
B22: 2401 | C22: Remove Fence | E22: 2421.99 | F22: =$D$6/$E$6*E22 -> 3337.9413 | G22: 811 | H22: LF | I22: =F22/G22 -> 4.1158339 | K22: =+J22*$I22 -> 0 | L22: =+Q22-K22 -> 0 | M22: =+R22-J22 -> 0 | P22: =O22*I22 -> 0 | Q22: =+V22-P22 -> 0 | R22: =+W22-O22 -> 0 | U22: =T22*D22 -> 0 | V22: =+AA22-U22 -> 0 | W22: =+AB22-T22 -> 0 | Z22: =Y22*I22 -> 0 | AA22: =+AF22-Z22 -> 0 | AB22: =+AG22-Y22 -> 0 | AD22: =$AD$21*G22/$G$21 -> 811
B23: 2490 | C23: Dump Fees | E23: 50.69 | F23: =$D$6/$E$6*E23 -> 69.860009 | G23: 2.03 | H23: TON | I23: =F23/G23 -> 34.413797 | K23: =+J23*$I23 -> 0 | L23: =+Q23-K23 -> 0 | M23: =+R23-J23 -> 0 | P23: =O23*I23 -> 0 | Q23: =+V23-P23 -> 0 | R23: =+W23-O23 -> 0 | U23: =T23*D23 -> 0 | V23: =+AA23-U23 -> 0 | W23: =+AB23-T23 -> 0 | Z23: =Y23*I23 -> 0 | AA23: =+AF23-Z23 -> 0 | AB23: =+AG23-Y23 -> 0 | AD23: =$AD$21*G23/$G$21 -> 2.03
B24: 2150 | C24: Export Trucking | E24: 14.71 | F24: =$D$6/$E$6*E24 -> 20.273047 | G24: 2.03 | H24: TON | I24: =F24/G24 -> 9.9867224 | K24: =+J24*$I24 -> 0 | L24: =+Q24-K24 -> 0 | M24: =+R24-J24 -> 0 | P24: =O24*I24 -> 0 | Q24: =+V24-P24 -> 0 | R24: =+W24-O24 -> 0 | U24: =T24*D24 -> 0 | V24: =+AA24-U24 -> 0 | W24: =+AB24-T24 -> 0 | Z24: =Y24*I24 -> 0 | AA24: =+AF24-Z24 -> 0 | AB24: =+AG24-Y24 -> 0 | AD24: =$AD$21*G24/$G$21 -> 2.03
C25: Remove PVC Pipe (08") WATER | E25: 159088.02 | F25: =$D$6/$E$6*E25 -> 219252.13 | G25: 3367 | H25: LF | I25: =F25/G25 -> 65.117948 | J25: 0 | K25: =+J25*$I25 -> 0 | L25: =+Q25-K25 -> 219252.13 | M25: =+R25-J25 -> 3367 | N25: =100%-(L25/$F25) -> 0 | O25: 0 | P25: =O25*I25 -> 0 | Q25: =+V25-P25 -> 219252.13 | R25: =+W25-O25 -> 3367 | S25: =100%-(Q25/$F25) -> 0 | T25: 0 | U25: =T25*D25 -> 0 | V25: =+AA25-U25 -> 219252.13 | W25: =+AB25-T25 -> 3367 | X25: =100%-(V25/$F25) -> 0 | Y25: 0 | Z25: =Y25*I25 -> 0 | AA25: =+AF25-Z25 -> 219252.13 | AB25: =+AG25-Y25 -> 3367 | AC25: =100%-(AA25/$F25) -> 0 | AD25: 0 | AE25: =AD25*I25 -> 0 | AF25: =F25-AE25 -> 219252.13 | AG25: =G25-AD25 -> 3367 | AH25: =100%-(AF25/$F25) -> 0
B26: 2450 | C26: Remove Pipe | E26: 130624.04 | F26: =$D$6/$E$6*E26 -> 180023.61 | G26: 3367 | H26: LF | I26: =F26/G26 -> 53.467064 | K26: =+J26*$I26 -> 0 | L26: =+Q26-K26 -> 0 | M26: =+R26-J26 -> 0 | P26: =O26*I26 -> 0 | Q26: =+V26-P26 -> 0 | R26: =+W26-O26 -> 0 | U26: =T26*D26 -> 0 | V26: =+AA26-U26 -> 0 | W26: =+AB26-T26 -> 0 | Y26: =$AD$25*B26/$G$25 -> 0 | Z26: =Y26*I26 -> 0 | AA26: =+AF26-Z26 -> 0 | AB26: =+AG26-Y26 -> 0 | AD26: =$AD$25*G26/$G$25 -> 0
B27: 2490 | C27: Dump Fees | E27: 480.64 | F27: =$D$6/$E$6*E27 -> 662.40905 | G27: 19.23 | H27: TON | I27: =F27/G27 -> 34.446648 | K27: =+J27*$I27 -> 0 | L27: =+Q27-K27 -> 0 | M27: =+R27-J27 -> 0 | P27: =O27*I27 -> 0 | Q27: =+V27-P27 -> 0 | R27: =+W27-O27 -> 0 | U27: =T27*D27 -> 0 | V27: =+AA27-U27 -> 0 | W27: =+AB27-T27 -> 0 | Y27: =$AD$25*B27/$G$25 -> 0 | Z27: =Y27*I27 -> 0 | AA27: =+AF27-Z27 -> 0 | AB27: =+AG27-Y27 -> 0 | AD27: =$AD$25*G27/$G$25 -> 0
B28: 2150 | C28: Export Trucking | E28: 139.46 | F28: =$D$6/$E$6*E28 -> 192.20116 | G28: 19.23 | H28: TON | I28: =F28/G28 -> 9.9948601 | K28: =+J28*$I28 -> 0 | L28: =+Q28-K28 -> 0 | M28: =+R28-J28 -> 0 | P28: =O28*I28 -> 0 | Q28: =+V28-P28 -> 0 | R28: =+W28-O28 -> 0 | U28: =T28*D28 -> 0 | V28: =+AA28-U28 -> 0 | W28: =+AB28-T28 -> 0 | Y28: =$AD$25*B28/$G$25 -> 0 | Z28: =Y28*I28 -> 0 | AA28: =+AF28-Z28 -> 0 | AB28: =+AG28-Y28 -> 0 | AD28: =$AD$25*G28/$G$25 -> 0
B29: 2172 | C29: Import Efill | E29: 8464.11 | F29: =$D$6/$E$6*E29 -> 11665.078 | G29: 971.1 | H29: TON | I29: =F29/G29 -> 12.012231 | K29: =+J29*$I29 -> 0 | L29: =+Q29-K29 -> 0 | M29: =+R29-J29 -> 0 | P29: =O29*I29 -> 0 | Q29: =+V29-P29 -> 0 | R29: =+W29-O29 -> 0 | U29: =T29*D29 -> 0 | V29: =+AA29-U29 -> 0 | W29: =+AB29-T29 -> 0 | Y29: =$AD$25*B29/$G$25 -> 0 | Z29: =Y29*I29 -> 0 | AA29: =+AF29-Z29 -> 0 | AB29: =+AG29-Y29 -> 0 | AD29: =$AD$25*G29/$G$25 -> 0
B30: 2149 | C30: Import Trucking | E30: 8233.24 | F30: =$D$6/$E$6*E30 -> 11346.897 | G30: 971.1 | H30: TON | I30: =F30/G30 -> 11.684582 | K30: =+J30*$I30 -> 0 | L30: =+Q30-K30 -> 0 | M30: =+R30-J30 -> 0 | P30: =O30*I30 -> 0 | Q30: =+V30-P30 -> 0 | R30: =+W30-O30 -> 0 | U30: =T30*D30 -> 0 | V30: =+AA30-U30 -> 0 | W30: =+AB30-T30 -> 0 | Y30: =$AD$25*B30/$G$25 -> 0 | Z30: =Y30*I30 -> 0 | AA30: =+AF30-Z30 -> 0 | AB30: =+AG30-Y30 -> 0 | AD30: =$AD$25*G30/$G$25 -> 0
B31: 2150 | C31: Export Trucking | E31: 8233.24 | F31: =$D$6/$E$6*E31 -> 11346.897 | G31: 971.1 | H31: TON | I31: =F31/G31 -> 11.684582 | K31: =+J31*$I31 -> 0 | L31: =+Q31-K31 -> 0 | M31: =+R31-J31 -> 0 | P31: =O31*I31 -> 0 | Q31: =+V31-P31 -> 0 | R31: =+W31-O31 -> 0 | U31: =T31*D31 -> 0 | V31: =+AA31-U31 -> 0 | W31: =+AB31-T31 -> 0 | Y31: =$AD$25*B31/$G$25 -> 0 | Z31: =Y31*I31 -> 0 | AA31: =+AF31-Z31 -> 0 | AB31: =+AG31-Y31 -> 0 | AD31: =$AD$25*G31/$G$25 -> 0
B32: 2490 | C32: Dump Fees | E32: 2913.3 | F32: =$D$6/$E$6*E32 -> 4015.0555 | G32: 971.1 | H32: TON | I32: =F32/G32 -> 4.1345438 | K32: =+J32*$I32 -> 0 | L32: =+Q32-K32 -> 0 | M32: =+R32-J32 -> 0 | P32: =O32*I32 -> 0 | Q32: =+V32-P32 -> 0 | R32: =+W32-O32 -> 0 | U32: =T32*D32 -> 0 | V32: =+AA32-U32 -> 0 | W32: =+AB32-T32 -> 0 | Y32: =$AD$25*B32/$G$25 -> 0 | Z32: =Y32*I32 -> 0 | AA32: =+AF32-Z32 -> 0 | AB32: =+AG32-Y32 -> 0 | AD32: =$AD$25*G32/$G$25 -> 0
C33: Remove PVC Pipe (08") SEWER | E33: 63206.44 | F33: =$D$6/$E$6*E33 -> 87109.932 | G33: 691 | H33: LF | I33: =F33/G33 -> 126.06358 | K33: =+J33*$I33 -> 0 | L33: =+Q33-K33 -> 87109.932 | M33: =+R33-J33 -> 691 | N33: =100%-(L33/$F33) -> 0 | P33: =O33*I33 -> 0 | Q33: =+V33-P33 -> 87109.932 | R33: =+W33-O33 -> 691 | S33: =100%-(Q33/$F33) -> 0 | U33: =T33*D33 -> 0 | V33: =+AA33-U33 -> 87109.932 | W33: =+AB33-T33 -> 691 | X33: =100%-(V33/$F33) -> 0 | Z33: =Y33*I33 -> 0 | AA33: =+AF33-Z33 -> 87109.932 | AB33: =+AG33-Y33 -> 691 | AC33: =100%-(AA33/$F33) -> 0 | AE33: =AD33*I33 -> 0 | AF33: =F33-AE33 -> 87109.932 | AG33: =G33-AD33 -> 691 | AH33: =100%-(AF33/$F33) -> 0
B34: 2450 | C34: Remove Pipe | E34: 40211.41 | F34: =$D$6/$E$6*E34 -> 55418.612 | G34: 691 | H34: LF | I34: =F34/G34 -> 80.200597 | K34: =+J34*$I34 -> 0 | L34: =+Q34-K34 -> 0 | M34: =+R34-J34 -> 0 | P34: =O34*I34 -> 0 | Q34: =+V34-P34 -> 0 | R34: =+W34-O34 -> 0 | U34: =T34*D34 -> 0 | V34: =+AA34-U34 -> 0 | W34: =+AB34-T34 -> 0 | Y34: =$AD$33*B34/$G$33 -> 0 | Z34: =Y34*I34 -> 0 | AA34: =+AF34-Z34 -> 0 | AB34: =+AG34-Y34 -> 0 | AD34: =$AD$33*G34/$G$33 -> 0
B35: 2490 | C35: Dump Fees | E35: 98.64 | F35: =$D$6/$E$6*E35 -> 135.9438 | G35: 3.95 | H35: TON | I35: =F35/G35 -> 34.416152 | K35: =+J35*$I35 -> 0 | L35: =+Q35-K35 -> 0 | M35: =+R35-J35 -> 0 | P35: =O35*I35 -> 0 | Q35: =+V35-P35 -> 0 | R35: =+W35-O35 -> 0 | U35: =T35*D35 -> 0 | V35: =+AA35-U35 -> 0 | W35: =+AB35-T35 -> 0 | Y35: =$AD$33*B35/$G$33 -> 0 | Z35: =Y35*I35 -> 0 | AA35: =+AF35-Z35 -> 0 | AB35: =+AG35-Y35 -> 0 | AD35: =$AD$33*G35/$G$33 -> 0
B36: 2150 | C36: Export Trucking | E36: 28.62 | F36: =$D$6/$E$6*E36 -> 39.443548 | G36: 3.95 | H36: TON | I36: =F36/G36 -> 9.9857084 | K36: =+J36*$I36 -> 0 | L36: =+Q36-K36 -> 0 | M36: =+R36-J36 -> 0 | P36: =O36*I36 -> 0 | Q36: =+V36-P36 -> 0 | R36: =+W36-O36 -> 0 | U36: =T36*D36 -> 0 | V36: =+AA36-U36 -> 0 | W36: =+AB36-T36 -> 0 | Y36: =$AD$33*B36/$G$33 -> 0 | Z36: =Y36*I36 -> 0 | AA36: =+AF36-Z36 -> 0 | AB36: =+AG36-Y36 -> 0 | AD36: =$AD$33*G36/$G$33 -> 0
B37: 2172 | C37: Import Efill | E37: 6951.45 | F37: =$D$6/$E$6*E37 -> 9580.3582 | G37: 797.55 | H37: TON | I37: =F37/G37 -> 12.012235 | K37: =+J37*$I37 -> 0 | L37: =+Q37-K37 -> 0 | M37: =+R37-J37 -> 0 | P37: =O37*I37 -> 0 | Q37: =+V37-P37 -> 0 | R37: =+W37-O37 -> 0 | U37: =T37*D37 -> 0 | V37: =+AA37-U37 -> 0 | W37: =+AB37-T37 -> 0 | Y37: =$AD$33*B37/$G$33 -> 0 | Z37: =Y37*I37 -> 0 | AA37: =+AF37-Z37 -> 0 | AB37: =+AG37-Y37 -> 0 | AD37: =$AD$33*G37/$G$33 -> 0
B38: 2149 | C38: Import Trucking | E38: 6761.84 | F38: =$D$6/$E$6*E38 -> 9319.0413 | G38: 797.55 | H38: TON | I38: =F38/G38 -> 11.684586 | K38: =+J38*$I38 -> 0 | L38: =+Q38-K38 -> 0 | M38: =+R38-J38 -> 0 | P38: =O38*I38 -> 0 | Q38: =+V38-P38 -> 0 | R38: =+W38-O38 -> 0 | U38: =T38*D38 -> 0 | V38: =+AA38-U38 -> 0 | W38: =+AB38-T38 -> 0 | Y38: =$AD$33*B38/$G$33 -> 0 | Z38: =Y38*I38 -> 0 | AA38: =+AF38-Z38 -> 0 | AB38: =+AG38-Y38 -> 0 | AD38: =$AD$33*G38/$G$33 -> 0
B39: 2150 | C39: Export Trucking | E39: 6761.84 | F39: =$D$6/$E$6*E39 -> 9319.0413 | G39: 797.55 | H39: TON | I39: =F39/G39 -> 11.684586 | K39: =+J39*$I39 -> 0 | L39: =+Q39-K39 -> 0 | M39: =+R39-J39 -> 0 | P39: =O39*I39 -> 0 | Q39: =+V39-P39 -> 0 | R39: =+W39-O39 -> 0 | U39: =T39*D39 -> 0 | V39: =+AA39-U39 -> 0 | W39: =+AB39-T39 -> 0 | Y39: =$AD$33*B39/$G$33 -> 0 | Z39: =Y39*I39 -> 0 | AA39: =+AF39-Z39 -> 0 | AB39: =+AG39-Y39 -> 0 | AD39: =$AD$33*G39/$G$33 -> 0
B40: 2490 | C40: Dump Fees | E40: 2392.65 | F40: =$D$6/$E$6*E40 -> 3297.5054 | G40: 797.55 | H40: TON | I40: =F40/G40 -> 4.1345438 | K40: =+J40*$I40 -> 0 | L40: =+Q40-K40 -> 0 | M40: =+R40-J40 -> 0 | P40: =O40*I40 -> 0 | Q40: =+V40-P40 -> 0 | R40: =+W40-O40 -> 0 | U40: =T40*D40 -> 0 | V40: =+AA40-U40 -> 0 | W40: =+AB40-T40 -> 0 | Y40: =$AD$33*B40/$G$33 -> 0 | Z40: =Y40*I40 -> 0 | AA40: =+AF40-Z40 -> 0 | AB40: =+AG40-Y40 -> 0 | AD40: =$AD$33*G40/$G$33 -> 0
...

Sheet Sheet2

Sheet Sheet1
A1: Item # | B1: Job Cost ID | C1: Description | E1: Total Direct Cost | F1: Quantity | G1: UM | H1: Total Bid Price | I1: Total Plug | J1: Total Labor | K1: Total Equip. | L1: Total Material | M1: Total Subcontracted | N1: Total Trucking
A2: 1 | C2: Temporary Erosion & Sediment Control | E2: 29138.084 | F2: 1 | G2: LS | H2: 40400 | I2: 0 | J2: 9053.2677 | K2: 5871.251 | L2: 9278.9553 | M2: 0 | N2: 4934.6105
B3: 2100 | C3: SWPPP | E3: 29138.084 | F3: 1 | G3: LS | I3: 0 | J3: 9053.2677 | K3: 5871.251 | L3: 9278.9553 | M3: 0 | N3: 4934.6105
A4: 2 | C4: Site Demolition | E4: 422513.36 | F4: 1 | G4: LS | H4: 582300 | I4: 0 | J4: 124610.32 | K4: 152212.82 | L4: 44681.631 | M4: 16900 | N4: 84108.58
B5: 2402 | C5: Tree Removal | E5: 16900 | F5: 1 | G5: LS | I5: 0 | J5: 0 | K5: 0 | L5: 0 | M5: 16900 | N5: 0
C6: Remove Concrete Flatwork 04" | E6: 16075.116 | F6: 17303 | G6: SF | I6: 0 | J6: 3351.4377 | K6: 3312.2886 | L6: 2850.6692 | M6: 0 | N6: 6560.7208
B7: 2420 | C7: Remove Concrete Flatwork | E7: 6663.7263 | F7: 17303 | G7: SF | I7: 0 | J7: 3351.4377 | K7: 3312.2886 | L7: 0 | M7: 0 | N7: 0
B8: 2490 | C8: Dump Fees | E8: 2850.6692 | F8: 432.575 | G8: TON | I8: 0 | J8: 0 | K8: 0 | L8: 2850.6692 | M8: 0 | N8: 0
B9: 2150 | C9: Export Trucking | E9: 6560.7208 | F9: 432.575 | G9: TON | I9: 0 | J9: 0 | K9: 0 | L9: 0 | M9: 0 | N9: 6560.7208
C10: Remove Asphalt SF (03") | E10: 98784.182 | F10: 147064 | G10: SF | I10: 0 | J10: 19939.495 | K10: 19706.576 | L10: 17316.786 | M10: 0 | N10: 41821.325
B11: 2410 | C11: Remove Asphalt | E11: 39646.071 | F11: 147064 | G11: SF | I11: 0 | J11: 19939.495 | K11: 19706.576 | L11: 0 | M11: 0 | N11: 0
B12: 2490 | C12: Dump Fees | E12: 17316.786 | F12: 2757.45 | G12: TON | I12: 0 | J12: 0 | K12: 0 | L12: 17316.786 | M12: 0 | N12: 0
B13: 2150 | C13: Export Trucking | E13: 41821.325 | F13: 2757.45 | G13: TON | I13: 0 | J13: 0 | K13: 0 | L13: 0 | M13: 0 | N13: 41821.325
C14: Remove Curb/Gutter 24" | E14: 11787.905 | F14: 1634 | G14: LF | I14: 0 | J14: 3164.9131 | K14: 4356.9443 | L14: 1292.1672 | M14: 0 | N14: 2973.88
B15: 2421 | C15: Remove Curb And Gutter | E15: 7521.8574 | F15: 1634 | G15: LF | I15: 0 | J15: 3164.9131 | K15: 4356.9443 | L15: 0 | M15: 0 | N15: 0
B16: 2490 | C16: Dump Fees | E16: 1292.1672 | F16: 196.08 | G16: TON | I16: 0 | J16: 0 | K16: 0 | L16: 1292.1672 | M16: 0 | N16: 0
B17: 2150 | C17: Export Trucking | E17: 2973.88 | F17: 196.08 | G17: TON | I17: 0 | J17: 0 | K17: 0 | L17: 0 | M17: 0 | N17: 2973.88
C18: Remove Chain Link Fence | E18: 2487.3841 | F18: 811 | G18: LF | I18: 0 | J18: 1721.9898 | K18: 700 | L18: 50.6875 | M18: 0 | N18: 14.706721
B19: 2401 | C19: Remove Fence | E19: 2421.9898 | F19: 811 | G19: LF | I19: 0 | J19: 1721.9898 | K19: 700 | L19: 0 | M19: 0 | N19: 0
B20: 2490 | C20: Dump Fees | E20: 50.6875 | F20: 2.0275 | G20: TON | I20: 0 | J20: 0 | K20: 0 | L20: 50.6875 | M20: 0 | N20: 0
B21: 2150 | C21: Export Trucking | E21: 14.706721 | F21: 2.0275 | G21: TON | I21: 0 | J21: 0 | K21: 0 | L21: 0 | M21: 0 | N21: 14.706721
C22: Remove PVC Pipe (08") WATER | E22: 159088.02 | F22: 3367 | G22: LF | I22: 0 | J22: 56348.018 | K22: 74276.02 | L22: 11858.05 | M22: 0 | N22: 16605.933
B23: 2450 | C23: Remove Pipe | E23: 130624.04 | F23: 3367 | G23: LF | I23: 0 | J23: 56348.018 | K23: 74276.02 | L23: 0 | M23: 0 | N23: 0
B24: 2490 | C24: Dump Fees | E24: 480.63925 | F24: 19.22557 | G24: TON | I24: 0 | J24: 0 | K24: 0 | L24: 480.63925 | M24: 0 | N24: 0
B25: 2150 | C25: Export Trucking | E25: 139.45504 | F25: 19.22557 | G25: TON | I25: 0 | J25: 0 | K25: 0 | L25: 0 | M25: 0 | N25: 139.45504
B26: 2172 | C26: Import Efill | E26: 8464.1105 | F26: 971.1 | G26: TON | I26: 0 | J26: 0 | K26: 0 | L26: 8464.1105 | M26: 0 | N26: 0
B27: 2149 | C27: Import Trucking | E27: 8233.2391 | F27: 971.1 | G27: TON | I27: 0 | J27: 0 | K27: 0 | L27: 0 | M27: 0 | N27: 8233.2391
B28: 2150 | C28: Export Trucking | E28: 8233.2391 | F28: 971.1 | G28: TON | I28: 0 | J28: 0 | K28: 0 | L28: 0 | M28: 0 | N28: 8233.2391
B29: 2490 | C29: Dump Fees | E29: 2913.3 | F29: 971.1 | G29: TON | I29: 0 | J29: 0 | K29: 0 | L29: 2913.3 | M29: 0 | N29: 0
C30: Remove PVC Pipe (08") SEWER | E30: 63206.442 | F30: 691 | G30: LF | I30: 0 | J30: 17346.219 | K30: 22865.19 | L30: 9442.7384 | M30: 0 | N30: 13552.294
B31: 2450 | C31: Remove Pipe | E31: 40211.409 | F31: 691 | G31: LF | I31: 0 | J31: 17346.219 | K31: 22865.19 | L31: 0 | M31: 0 | N31: 0
B32: 2490 | C32: Dump Fees | E32: 98.64025 | F32: 3.94561 | G32: TON | I32: 0 | J32: 0 | K32: 0 | L32: 98.64025 | M32: 0 | N32: 0
B33: 2150 | C33: Export Trucking | E33: 28.619968 | F33: 3.94561 | G33: TON | I33: 0 | J33: 0 | K33: 0 | L33: 0 | M33: 0 | N33: 28.619968
B34: 2172 | C34: Import Efill | E34: 6951.4482 | F34: 797.55 | G34: TON | I34: 0 | J34: 0 | K34: 0 | L34: 6951.4482 | M34: 0 | N34: 0
B35: 2149 | C35: Import Trucking | E35: 6761.837 | F35: 797.55 | G35: TON | I35: 0 | J35: 0 | K35: 0 | L35: 0 | M35: 0 | N35: 6761.837
B36: 2150 | C36: Export Trucking | E36: 6761.837 | F36: 797.55 | G36: TON | I36: 0 | J36: 0 | K36: 0 | L36: 0 | M36: 0 | N36: 6761.837
B37: 2490 | C37: Dump Fees | E37: 2392.65 | F37: 797.55 | G37: TON | I37: 0 | J37: 0 | K37: 0 | L37: 2392.65 | M37: 0 | N37: 0
C38: Remove Pipe RCP 15" | E38: 32781.999 | F38: 1069 | G38: LF | I38: 0 | J38: 13417.589 | K38: 17686.605 | L38: 648.26833 | M38: 0 | N38: 1029.5361
B39: 2450 | C39: Remove Pipe | E39: 31104.194 | F39: 1069 | G39: LF | I39: 0 | J39: 13417.589 | K39: 17686.605 | L39: 0 | M39: 0 | N39: 0
B40: 2490 | C40: Dump Fees | E40: 648.26833 | F40: 67.8815 | G40: TON | I40: 0 | J40: 0 | K40: 0 | L40: 648.26833 | M40: 0 | N40: 0
...
